Workbook
Name Categorie: Ressources!$K$2:$K$5
Name Catégories: #REF!
Name Num_Compte: Ressources!$A$2:$A$6
Name Segment_Compte: #N/A
Name Type_Compte: Ressources!$B$2:$B$6

Sheet Tableau de bord - Portefeuille
B1: Vue globale de mon portefeuille
D2: Tous les comptes sont convertis en CAD
B3: Notes | D3: Marge (CA) | G3: Valeur total | J3: =E4+E12+E20+E28+E36+B38 -> 677602.59 | O3: Plus grande variation du jour
B4: Prochain achat US : PPL JD TCEHY Remplir mon REER (PRIORITÉ) | D4: Valeur au marché | E4: =SUMIF(Titres[Compte],"Marge (CAD)",Titres[Valeur au marché ($ local)]) -> 253641.8 | G4: Coût total | J4: ='Titre et dividendes'!L79 -> 388303.04 | N4: 1 | O4: Gagnant : | P4: =_xlfn.XLOOKUP(MAX(Titres[Variation du jour ($)]),Titres[Variation du jour ($)],Titres[Action]) -> #VALUE!
D5: Gain ($) | E5: =SUMIF(Titres[Compte],"Marge (CAD)",Titres[Gain non réalisé ($)]) -> 86721.65 | G5: Gain ($) | J5: ='Titre et dividendes'!R79 -> 238690.98 | P5: =_xlfn.XLOOKUP(P4,Titres[Action],Titres[Variation du jour ($)]) -> 383.94
D6: Gain (%) | E6: =SUMIF(Titres[Compte],"Marge (CAD)",Titres[Gain non réalisé ($)])/SUMIF(Titres[Compte],"Marge (CAD)",Titres[Coût total]) -> 0.51953973 | G6: Gain (%) | J6: =J5/J3 -> 0.35225807 | P6: =_xlfn.XLOOKUP(P4,Titres[Action],Titres[Variation du jour (%)]) -> 0.019260492
D7: Revenu annuel anticipé | E7: =SUMIF(Titres[Compte],"Marge (CAD)",Titres[Revenu annuel anticipé]) -> 5793.84 | G7: Variation du jour ($) | J7: ='Titre et dividendes'!P79 -> -4389.715 | N7: -1 | O7: Perdant : | P7: =_xlfn.XLOOKUP(MIN(Titres[Variation du jour ($)]),Titres[Variation du jour ($)],Titres[Action]) -> #VALUE!
D8: Rendement | E8: =E7/E4 -> 0.022842607 | G8: Variation du jour (%) | J8: ='Titre et dividendes'!Q79 -> -0.0069525311 | P8: =_xlfn.XLOOKUP(P7,Titres[Action],Titres[Variation du jour ($)]) -> -1957
D9: Liquidité | E9: 0 | P9: =_xlfn.XLOOKUP(P7,Titres[Action],Titres[Variation du jour (%)]) -> -0.014021236
G10: #VALUE!
D11: Marge (US) | G11: Prix | I11: {=_FV(G10,"Prix")} -> 33808.3
D12: Valeur au marché | E12: =Ressources!I3*SUMIF(Titres[Compte],"Marge (USD)",Titres[Valeur au marché ($ local)]) -> 8747.864 | G12: Variation du jour ($) | I12: {=I11-_FV(G10,"Clôture précédente",TRUE)} -> -551.73
D13: Gain ($) | E13: =Ressources!I3*SUMIF(Titres[Compte],"Marge (USD)",Titres[Gain non réalisé ($)]) -> -213.096 | G13: Variation du jour (%) | I13: =I12/(I11-I12) -> -0.01605732
D14: Gain (%) | E14: =SUMIF(Titres[Compte],"Marge (USD)",Titres[Gain non réalisé ($)])/SUMIF(Titres[Compte],"Marge (USD)",Titres[Coût total]) -> -0.023780488
D15: Revenu annuel anticipé | E15: =SUMIF(Titres[Compte],"Marge (USD)",Titres[Revenu annuel anticipé]) -> 324 | G15: #VALUE!
D16: Rendement | E16: =E15/E12 -> 0.037037613 | G16: Prix | I16: {=_FV(G15,"Prix")} -> 7064.01
D17: Liquidité | E17: =Ressources!I3*-3144.92 -> -4295.9607 | G17: Variation du jour ($) | I17: {=I16-_FV(G15,"Clôture précédente",TRUE)} -> -45.13
G18: Variation du jour (%) | I18: =I17/(I16-I17) -> -0.0063481659
D19: CELI
D20: Valeur au marché | E20: =SUMIF(Titres[Compte],"CELI (CAD)",Titres[Valeur au marché ($ local)]) -> 262273.61 | G20: Dividende annuel estimé | I20: Dividende mensuel moyen | K20: ="Dividendes "&RIGHT(M20,4)-1 -> Dividendes 2025 | M20: Dividendes 2026
D21: Gain ($) | E21: =SUMIF(Titres[Compte],"CELI (CAD)",Titres[Gain non réalisé ($)]) -> 112596.91 | G21: =Titres[[#Totals],[Revenu annuel anticipé]] -> 17184.78 | I21: =G21/12 -> 1432.065 | K21: =SUMIF('Titre et dividendes'!$AB$5:$XFD$5,_xlfn.CONCAT("*",RIGHT(M20,4)-1),'Titre et dividendes'!$AB$79:$XFD$79) -> 13549.22 | M21: =SUMIF('Titre et dividendes'!$AB$5:$XFD$5,_xlfn.CONCAT("*",RIGHT(M20,4)),'Titre et dividendes'!$AB$79:$XFD$79) -> 2910.24
D22: Gain (%) | E22: =SUMIF(Titres[Compte],"CELI (CAD)",Titres[Gain non réalisé ($)])/SUMIF(Titres[Compte],"CELI (CAD)",Titres[Coût total]) -> 0.75226749
D23: Revenu annuel anticipé | E23: =SUMIF(Titres[Compte],"CELI (CAD)",Titres[Revenu annuel anticipé]) -> 8092.58 | M23: ="MaJ de "&LOOKUP("zz",'Titre et dividendes'!5:5) -> MaJ de Février 2026
D24: Rendement | E24: =E23/E20 -> 0.030855487 | G24: Projections de mon portefeuille
D25: Liquidité | E25: 1386.72 | G25: Réinvestissement | H25: Dividendes mensuels | J25: Dividendes à venir | L25: Valeur du portefeuille
G26: ="Dans 5 ans ("&YEAR(TODAY())-1984+5&" ans)" -> Dans 5 ans (47 ans) | H26: =IF($G$25="Réinvestissement",_xlfn.XLOOKUP(DATE(YEAR(TODAY())+5,MONTH(TODAY()),1),Projection!$F$12:$F$503,Projection!$M$12:$M$503),_xlfn.XLOOKUP(DATE(YEAR(TODAY())+5,MONTH(TODAY()),1),Projection!$F$12:$F$503,Projection!$L$12:$L$503)) -> 3034.9346 | J26: =IF($G$25="Réinvestissement",_xlfn.XLOOKUP(DATE(YEAR(TODAY())+5,MONTH(TODAY()),1),Projection!$F$12:$F$503,Projection!$P$12:$P$503),_xlfn.XLOOKUP(DATE(YEAR(TODAY())+5,MONTH(TODAY()),1),Projection!$F$12:$F$503,Projection!$O$12:$O$503)) -> 151912.25 | L26: =IF($G$25="Réinvestissement",_xlfn.XLOOKUP(DATE(YEAR(TODAY())+5,MONTH(TODAY()),1),Projection!$F$12:$F$503,Projection!$S$12:$S$503),_xlfn.XLOOKUP(DATE(YEAR(TODAY())+5,MONTH(TODAY()),1),Projection!$F$12:$F$503,Projection!$R$12:$R$503)) -> 1093830.8
D27: REER | G27: ="Dans 10 ans ("&YEAR(TODAY())-1984+10&" ans)" -> Dans 10 ans (52 ans) | H27: =+IF($G$25="Réinvestissement",_xlfn.XLOOKUP(DATE(YEAR(TODAY())+10,MONTH(TODAY()),1),Projection!$F$12:$F$503,Projection!$M$12:$M$503),_xlfn.XLOOKUP(DATE(YEAR(TODAY())+10,MONTH(TODAY()),1),Projection!$F$12:$F$503,Projection!$L$12:$L$503)) -> 4292.9861 | J27: =IF($G$25="Réinvestissement",_xlfn.XLOOKUP(DATE(YEAR(TODAY())+10,MONTH(TODAY()),1),Projection!$F$12:$F$503,Projection!$P$12:$P$503),_xlfn.XLOOKUP(DATE(YEAR(TODAY())+10,MONTH(TODAY()),1),Projection!$F$12:$F$503,Projection!$O$12:$O$503)) -> 371315.15 | L27: =IF($G$25="Réinvestissement",_xlfn.XLOOKUP(DATE(YEAR(TODAY())+10,MONTH(TODAY()),1),Projection!$F$12:$F$503,Projection!$S$12:$S$503),_xlfn.XLOOKUP(DATE(YEAR(TODAY())+10,MONTH(TODAY()),1),Projection!$F$12:$F$503,Projection!$R$12:$R$503)) -> 1626476.9
D28: Valeur au marché | E28: =SUMIF(Titres[Compte],"REER (USD)",Titres[Valeur au marché (CAD)]) -> 142985.51 | G28: ="Dans 15 ans ("&YEAR(TODAY())-1984+15&" ans)" -> Dans 15 ans (57 ans) | H28: =+IF($G$25="Réinvestissement",_xlfn.XLOOKUP(DATE(YEAR(TODAY())+15,MONTH(TODAY()),1),Projection!$F$12:$F$503,Projection!$M$12:$M$503),_xlfn.XLOOKUP(DATE(YEAR(TODAY())+15,MONTH(TODAY()),1),Projection!$F$12:$F$503,Projection!$L$12:$L$503)) -> 5777.948 | J28: =IF($G$25="Réinvestissement",_xlfn.XLOOKUP(DATE(YEAR(TODAY())+15,MONTH(TODAY()),1),Projection!$F$12:$F$503,Projection!$P$12:$P$503),_xlfn.XLOOKUP(DATE(YEAR(TODAY())+15,MONTH(TODAY()),1),Projection!$F$12:$F$503,Projection!$O$12:$O$503)) -> 672979.58 | L28: =IF($G$25="Réinvestissement",_xlfn.XLOOKUP(DATE(YEAR(TODAY())+15,MONTH(TODAY()),1),Projection!$F$12:$F$503,Projection!$S$12:$S$503),_xlfn.XLOOKUP(DATE(YEAR(TODAY())+15,MONTH(TODAY()),1),Projection!$F$12:$F$503,Projection!$R$12:$R$503)) -> 2301175.2
D29: Gain ($) | E29: =SUMIF(Titres[Compte],"REER (USD)",Titres[Gain non réalisé ($)]) -> 39528.415 | G29: ="Dans 20 ans ("&YEAR(TODAY())-1984+20&" ans)" -> Dans 20 ans (62 ans) | H29: =IF($G$25="Réinvestissement",_xlfn.XLOOKUP(DATE(YEAR(TODAY())+20,MONTH(TODAY()),1),Projection!$F$12:$F$503,Projection!$M$12:$M$503),_xlfn.XLOOKUP(DATE(YEAR(TODAY())+20,MONTH(TODAY()),1),Projection!$F$12:$F$503,Projection!$L$12:$L$503)) -> 7519.3 | J29: =IF($G$25="Réinvestissement",_xlfn.XLOOKUP(DATE(YEAR(TODAY())+20,MONTH(TODAY()),1),Projection!$F$12:$F$503,Projection!$P$12:$P$503),_xlfn.XLOOKUP(DATE(YEAR(TODAY())+20,MONTH(TODAY()),1),Projection!$F$12:$F$503,Projection!$O$12:$O$503)) -> 1071409.3 | L29: =IF($G$25="Réinvestissement",_xlfn.XLOOKUP(DATE(YEAR(TODAY())+20,MONTH(TODAY()),1),Projection!$F$12:$F$503,Projection!$S$12:$S$503),_xlfn.XLOOKUP(DATE(YEAR(TODAY())+20,MONTH(TODAY()),1),Projection!$F$12:$F$503,Projection!$R$12:$R$503)) -> 3148046
B30: Nb de titres | D30: Gain (%) | E30: =SUMIF(Titres[Compte],"REER (USD)",Titres[Gain non réalisé ($)])/SUMIF(Titres[Compte],"REER (USD)",Titres[Coût total]) -> 0.6067648 | G30: ="Dans 25 ans ("&YEAR(TODAY())-1984+25&" ans)" -> Dans 25 ans (67 ans) | H30: =IF($G$25="Réinvestissement",_xlfn.XLOOKUP(DATE(YEAR(TODAY())+25,MONTH(TODAY()),1),Projection!$F$12:$F$503,Projection!$M$12:$M$503),_xlfn.XLOOKUP(DATE(YEAR(TODAY())+25,MONTH(TODAY()),1),Projection!$F$12:$F$503,Projection!$L$12:$L$503)) -> 9548.5011 | J30: =IF($G$25="Réinvestissement",_xlfn.XLOOKUP(DATE(YEAR(TODAY())+25,MONTH(TODAY()),1),Projection!$F$12:$F$503,Projection!$P$12:$P$503),_xlfn.XLOOKUP(DATE(YEAR(TODAY())+25,MONTH(TODAY()),1),Projection!$F$12:$F$503,Projection!$O$12:$O$503)) -> 1582937.4 | L30: =IF($G$25="Réinvestissement",_xlfn.XLOOKUP(DATE(YEAR(TODAY())+25,MONTH(TODAY()),1),Projection!$F$12:$F$503,Projection!$S$12:$S$503),_xlfn.XLOOKUP(DATE(YEAR(TODAY())+25,MONTH(TODAY()),1),Projection!$F$12:$F$503,Projection!$R$12:$R$503)) -> 4202294.5
B31: =Titres[[#Totals],[Symbole]] -> 73 | D31: Revenu annuel anticipé | E31: =SUMIF(Titres[Compte],"REER (USD)",Titres[Revenu annuel anticipé]) -> 2974.36 | G31: ="Dans 30 ans ("&YEAR(TODAY())-1984+30&" ans)" -> Dans 30 ans (72 ans) | H31: =IF($G$25="Réinvestissement",_xlfn.XLOOKUP(DATE(YEAR(TODAY())+30,MONTH(TODAY()),1),Projection!$F$12:$F$503,Projection!$M$12:$M$503),_xlfn.XLOOKUP(DATE(YEAR(TODAY())+30,MONTH(TODAY()),1),Projection!$F$12:$F$503,Projection!$L$12:$L$503)) -> 11898.93 | J31: =IF($G$25="Réinvestissement",_xlfn.XLOOKUP(DATE(YEAR(TODAY())+30,MONTH(TODAY()),1),Projection!$F$12:$F$503,Projection!$P$12:$P$503),_xlfn.XLOOKUP(DATE(YEAR(TODAY())+30,MONTH(TODAY()),1),Projection!$F$12:$F$503,Projection!$O$12:$O$503)) -> 2225843.4 | L31: =IF($G$25="Réinvestissement",_xlfn.XLOOKUP(DATE(YEAR(TODAY())+30,MONTH(TODAY()),1),Projection!$F$12:$F$503,Projection!$S$12:$S$503),_xlfn.XLOOKUP(DATE(YEAR(TODAY())+30,MONTH(TODAY()),1),Projection!$F$12:$F$503,Projection!$R$12:$R$503)) -> 5504866.9
D32: Rendement | E32: =E31/E28 -> 0.020801828 | G32: ="À "&H36&" ans (Retraite)" -> À 55 ans (Retraite) | H32: =IF($G$25="Réinvestissement",_xlfn.XLOOKUP(DATE(1984+H36,6,1),Projection!$F$12:$F$503,Projection!$M$12:$M$503),_xlfn.XLOOKUP(DATE(1984+H36,6,1),Projection!$F$12:$F$503,Projection!$L$12:$L$503)) -> 5205.2948 | J32: =IF($G$25="Réinvestissement",_xlfn.XLOOKUP(DATE(1984+H36,6,1),Projection!$F$12:$F$503,Projection!$P$12:$P$503),_xlfn.XLOOKUP(DATE(1984+H36,6,1),Projection!$F$12:$F$503,Projection!$O$12:$O$503)) -> 551939.24 | L32: =IF($G$25="Réinvestissement",_xlfn.XLOOKUP(DATE(1984+H36,6,1),Projection!$F$12:$F$503,Projection!$S$12:$S$503),_xlfn.XLOOKUP(DATE(1984+H36,6,1),Projection!$F$12:$F$503,Projection!$R$12:$R$503)) -> 2035491.3
D33: Liquidité | E33: =Ressources!I3*724.4 -> 989.5304
G34: Planification du revenu à la retraite
D35: CRCD | G35: Objectifs | I35: RRMD | K35: Placements | M35: Total
D36: Valeur au marché | E36: =Tableau4[[#Totals],[Valeur marchande]] -> 11873.511 | G36: Âge de la retraite | H36: 55 | I36: =_xlfn.XLOOKUP(H36,RRMD!B:B,RRMD!G:G) -> 46454.641 | K36: =(IF($G$25="Réinvestissement",_xlfn.XLOOKUP(DATE(1984+H36,6,1),Projection!$F$12:$F$503,Projection!$M$12:$M$503),_xlfn.XLOOKUP(DATE(1984+H36,6,1),Projection!$F$12:$F$503,Projection!$L$12:$L$503)))*12 -> 62463.538 | M36: =I36+K36 -> 108918.18
B37: Liquidités | D37: Gain ($) | E37: =Tableau4[[#Totals],[Gain ($)]] -> 873.51599 | G37: % du salaire actuel | H37: 0.7
B38: =E9+E17+E25+E33 -> -1919.7103 | D38: Gain (%) | E38: =Tableau4[[#Totals],[Gain (%)]] -> 0.079410579 | G38: =H37*Ressources!G2 -> 90380.843 | H38: ↙ | M38: =M36/G38 -> 1.2051025
F44: TSX : | G44: {=TRANSPOSE(_xlfn.STOCKHISTORY(G10,TODAY()-365,TODAY(),0,0,1))} -> 24008.86 | H44: 24305.98 | I44: 24472.68 | J44: 24727.53 | K44: 24710.51 | L44: 24798.59 | M44: 24874.48 | N44: 24841.68 | O44: 24795.55 | P44: 25031.51 | Q44: 24953.52 | R44: 24974.72 | S44: 25161.18 | T44: 25254.06 | U44: 25357.74 | V44: 25532.18 | W44: 25616.86 | X44: 25692.45 | Y44: 25897.48 | Z44: 25971.93 | AA44: 26055.63 | AB44: 25839.17 | AC44: 25854.01 | AD44: 25879.95 | AE44: 26073.13 | AF44: 26269 | AG44: 26283.45 | AH44: 26210.56 | AI44: 26175.05 | AJ44: 26388.96 | AK44: 26426.64 | AL44: 26329 | AM44: 26342.29 | AN44: 26429.13 | AO44: 26375.8 | AP44: 26426.31 | AQ44: 26524.16 | AR44: 26615.75 | AS44: 26504.35 | AT44: 26568.61 | AU44: 26541.39 | AV44: 26559.85 | AW44: 26506 | AX44: 26497.57 | AY44: 26609.36 | AZ44: 26718.62 | BA44: 26566.32 | BB44: 26751.95 | BC44: 26692.32 | BD44: 26857.11 | BE44: 26869.66 | BF44: 27034.26 | BG44: 27036.16 | BH44: 27020.28 | BI44: 26903.57 | BJ44: 26972.32 | BK44: 27082.3 | BL44: 27023.25 | BM44: 27198.85 | BN44: 27054.14 | BO44: 27152.97 | BP44: 27386.93 | BQ44: 27314.01 | BR44: 27317 | BS44: 27364.43 | BT44: 27416.41 | BU44: 27372.26 | BV44: 27494.35 | BW44: 27405.42 | BX44: 27539.88 | BY44: 27369.96 | BZ44: 27259.78 | CA44: 27020.43 | CB44: 27570.08 | CC44: 27920.87 | CD44: 27761.27 | CE44: 27758.68 | CF44: 27775.23 | CG44: 27921.26 | CH44: 27993.43 | CI44: 27915.99 | CJ44: 27905.49 | CK44: 27922.85 | CL44: 27823.88 | CM44: 27878.76 | CN44: 28055.43 | CO44: 28333.13 | CP44: 28169.94 | CQ44: 28339.88 | CR44: 28433 | CS44: 28434.8 | CT44: 28564.45 | CU44: 28615.62 | CV44: 28751.36 | CW44: 28915.89 | CX44: 29050.63 | CY44: 29027.73 | CZ44: 29063.01 | DA44: 29179.39 | DB44: 29407.89 | DC44: 29283.82 | DD44: 29431.02 | DE44: 29315.23 | DF44: 29321.66 | DG44: 29453.53 | DH44: 29768.36 | DI44: 29958.98 | DJ44: 29815.63 | DK44: 29756.95 | DL44: 29731.98 | DM44: 29761.28 | DN44: 29971.91 | DO44: 30022.81 | DP44: 30107.67 | DQ44: 30160.59 | DR44: 30471.68 | DS44: 30531.88 | DT44: 30351.72 | DU44: 30501.99 | DV44: 30269.98 | DW44: 29850.89 | DX44: 30353.61 | DY44: 30637.12 | DZ44: 30458.8 | EA44: 30108.48 | EB44: 30416.44 | EC44: 29888.82 | ED44: 29982.98 | EE44: 30186.28 | EF44: 30353.07 | EG44: 30275.76 | EH44: 30419.68 | EI44: 30144.78 | EJ44: 30178.98 | EK44: 30260.74 | EL44: 30275.06 | EM44: 29777.82 | EN44: 30103.48 | EO44: 29868.59 | EP44: 29912.19 | EQ44: 30316.63 | ER44: 30409.25 | ES44: 30827.58 | ET44: 30253.64 | EU44: 30326.46 | EV44: 30076.21 | EW44: 30036.46 | EX44: 30278.41 | EY44: 29906.55 | EZ44: 30160.65 | FA44: 30604.35 | FB44: 30900.65 | FC44: 31180.25 | FD44: 31196.71 | FE44: 31382.78 | FF44: 31101.78 | FG44: 31049.28 | FH44: 31160.54 | FI44: 31477.57 | FJ44: 31311.41 | FK44: 31169.97 | FL44: 31244.37 | FM44: 31490.85 | FN44: 31660.73 | FO44: 31527.39 | FP44: 31483.44 | FQ44: 31263.93 | FR44: 31250.02 | FS44: 31440.85 | FT44: 31755.77 | FU44: 32000.1 | FV44: 32058.73 | FW44: 31999.76 | FX44: 31896.59 | FY44: 31866.26 | FZ44: 31712.76 | GA44: 31883.37 | GB44: 32219.95 | GC44: 32407.02 | GD44: 32135.49 | GE44: 32378.64 | GF44: 32612.93 | GG44: 32874.7 | GH44: 32870.36 | GI44: 32916.47 | GJ44: 33028.92 | GK44: 33040.55 | GL44: 33090.96 | GM44: 32750.28 | GN44: 32851.53 | GO44: 33002.7 | GP44: 33144.98 | GQ44: 33093.32 | GR44: 33096.4 | GS44: 33176.07 | GT44: 33016.13 | GU44: 31923.52 | GV44: 32183.88 | GW44: 32388.6 | GX44: 32571.55 | GY44: 31994.6 | GZ44: 32470.98 | HA44: 33023.32 | HB44: 33256.83 | HC44: 33254.19 | HD44: 32465.28 | HE44: 33073.71 | HF44: 32896.55 | HG44: 33389.73 | HH44: 33594.98 | HI44: 33817.51 | HJ44: 33776.5 | HK44: 33970.38 | HL44: 34127.33 | HM44: 34501.96 | HN44: 34339.99 | HO44: 34541.27 | HP44: 33784.94 | HQ44: 33942.86 | HR44: 33609.97 | HS44: 33083.72 | HT44: 33189.32 | HU44: 33270.65 | HV44: 33119.83 | HW44: 32840.6 | HX44: 32541.93 | HY44: 32876.65 | HZ44: 32929.09 | IA44: 32312.67 | IB44: 31854.98 | IC44: 31317.41 | ID44: 31883.81 | IE44: 31941.59 | IF44: 32382.6 | IG44: 31887.52 | IH44: 31960.65 | II44: 31934.94 | IJ44: 32768.04 | IK44: 32957.95 | IL44: 33108.22 | IM44: #N/A | IN44: 33181.97 | IO44: 33237.52 | IP44: 33620.57 | IQ44: 33477.71 | IR44: 33695.76 | IS44: 33879.24 | IT44: 34102.36 | IU44: 34155.99 | IV44: 34052.23 | IW44: 34346.29 | IX44: 34360.03
F45: S&P : | G45: {=TRANSPOSE(_xlfn.STOCKHISTORY(G15,TODAY()-365,TODAY(),0,0,1))} -> 5158.2 | H45: 5287.76 | I45: 5375.86 | J45: 5484.77 | K45: 5525.21 | L45: 5528.75 | M45: 5560.83 | N45: 5569.06 | O45: 5604.14 | P45: 5686.67 | Q45: 5650.38 | R45: 5606.91 | S45: 5631.28 | T45: 5663.94 | U45: 5659.91 | V45: 5844.19 | W45: 5886.55 | X45: 5892.58 | Y45: 5916.93 | Z45: 5958.38 | AA45: 5963.6 | AB45: 5940.46 | AC45: 5844.61 | AD45: 5842.01 | AE45: 5802.82 | AF45: 5921.54 | AG45: 5888.55 | AH45: 5912.17 | AI45: 5911.69 | AJ45: 5935.94 | AK45: 5970.37 | AL45: 5970.81 | AM45: 5939.3 | AN45: 6000.36 | AO45: 6005.88 | AP45: 6038.81 | AQ45: 6022.24 | AR45: 6045.26 | AS45: 5976.97 | AT45: 6033.11 | AU45: 5982.72 | AV45: 5980.87 | AW45: 5967.84 | AX45: 6025.17 | AY45: 6092.18 | AZ45: 6092.16 | BA45: 6141.02 | BB45: 6173.07 | BC45: 6204.95 | BD45: 6198.01 | BE45: 6227.42 | BF45: 6279.35 | BG45: 6229.98 | BH45: 6225.52 | BI45: 6263.26 | BJ45: 6280.46 | BK45: 6259.75 | BL45: 6268.56 | BM45: 6243.76 | BN45: 6263.7 | BO45: 6297.36 | BP45: 6296.79 | BQ45: 6305.6 | BR45: 6309.62 | BS45: 6358.91 | BT45: 6363.35 | BU45: 6388.64 | BV45: 6389.77 | BW45: 6370.86 | BX45: 6362.9 | BY45: 6339.39 | BZ45: 6238.01 | CA45: 6329.94 | CB45: 6299.19 | CC45: 6345.06 | CD45: 6340 | CE45: 6389.45 | CF45: 6373.45 | CG45: 6445.76 | CH45: 6466.58 | CI45: 6468.54 | CJ45: 6449.8 | CK45: 6449.15 | CL45: 6411.37 | CM45: 6395.78 | CN45: 6370.17 | CO45: 6466.91 | CP45: 6439.32 | CQ45: 6465.94 | CR45: 6481.4 | CS45: 6501.86 | CT45: 6460.26 | CU45: 6415.54 | CV45: 6448.26 | CW45: 6502.08 | CX45: 6481.5 | CY45: 6495.15 | CZ45: 6512.61 | DA45: 6532.04 | DB45: 6587.47 | DC45: 6584.29 | DD45: 6615.28 | DE45: 6606.76 | DF45: 6600.35 | DG45: 6631.96 | DH45: 6664.36 | DI45: 6693.75 | DJ45: 6656.92 | DK45: 6637.97 | DL45: 6604.72 | DM45: 6643.7 | DN45: 6661.21 | DO45: 6688.46 | DP45: 6711.2 | DQ45: 6715.35 | DR45: 6715.79 | DS45: 6740.28 | DT45: 6714.59 | DU45: 6753.72 | DV45: 6735.11 | DW45: 6552.51 | DX45: 6654.72 | DY45: 6644.31 | DZ45: 6671.06 | EA45: 6629.07 | EB45: 6664.01 | EC45: 6735.13 | ED45: 6735.35 | EE45: 6699.4 | EF45: 6738.44 | EG45: 6791.69 | EH45: 6875.16 | EI45: 6890.89 | EJ45: 6890.59 | EK45: 6822.34 | EL45: 6840.2 | EM45: 6851.97 | EN45: 6771.55 | EO45: 6796.29 | EP45: 6720.32 | EQ45: 6728.8 | ER45: 6832.43 | ES45: 6846.61 | ET45: 6850.92 | EU45: 6737.49 | EV45: 6734.11 | EW45: 6672.41 | EX45: 6617.32 | EY45: 6642.16 | EZ45: 6538.76 | FA45: 6602.99 | FB45: 6705.12 | FC45: 6765.88 | FD45: 6812.61 | FE45: 6849.09 | FF45: 6812.63 | FG45: 6829.37 | FH45: 6849.72 | FI45: 6857.12 | FJ45: 6870.4 | FK45: 6846.51 | FL45: 6840.51 | FM45: 6886.68 | FN45: 6901 | FO45: 6827.41 | FP45: 6816.51 | FQ45: 6800.26 | FR45: 6721.43 | FS45: 6774.76 | FT45: 6834.5 | FU45: 6878.49 | FV45: 6909.79 | FW45: 6932.05 | FX45: 6929.94 | FY45: 6905.74 | FZ45: 6896.24 | GA45: 6845.5 | GB45: 6858.47 | GC45: 6902.05 | GD45: 6944.82 | GE45: 6920.93 | GF45: 6921.46 | GG45: 6966.28 | GH45: 6977.27 | GI45: 6963.74 | GJ45: 6926.6 | GK45: 6944.47 | GL45: 6940.01 | GM45: 6796.86 | GN45: 6875.62 | GO45: 6913.35 | GP45: 6915.61 | GQ45: 6950.23 | GR45: 6978.6 | GS45: 6978.03 | GT45: 6969.01 | GU45: 6939.03 | GV45: 6976.44 | GW45: 6917.81 | GX45: 6882.72 | GY45: 6798.4 | GZ45: 6932.3 | HA45: 6964.82 | HB45: 6941.81 | HC45: 6941.47 | HD45: 6832.76 | HE45: 6836.17 | HF45: 6843.22 | HG45: 6881.31 | HH45: 6861.89 | HI45: 6909.51 | HJ45: 6837.75 | HK45: 6890.07 | HL45: 6946.13 | HM45: 6908.86 | HN45: 6878.88 | HO45: 6881.62 | HP45: 6816.63 | HQ45: 6869.5 | HR45: 6830.71 | HS45: 6740.02 | HT45: 6795.99 | HU45: 6781.48 | HV45: 6775.8 | HW45: 6672.62 | HX45: 6632.19 | HY45: 6699.38 | HZ45: 6716.09 | IA45: 6624.7 | IB45: 6606.49 | IC45: 6506.48 | ID45: 6581 | IE45: 6556.37 | IF45: 6591.9 | IG45: 6477.16 | IH45: 6368.85 | II45: 6343.72 | IJ45: 6528.52 | IK45: 6575.32 | IL45: 6582.69 | IM45: 6611.83 | IN45: 6616.85 | IO45: 6782.81 | IP45: 6824.66 | IQ45: 6816.89 | IR45: 6886.24 | IS45: 6967.38 | IT45: 7022.95 | IU45: 7041.28 | IV45: 7126.06 | IW45: 7109.14

Sheet Titre et dividendes
B1: Liste de suivi des titres et des dividendes mensuels
B5: # de compte | C5: Compte | D5: Action | E5: Symbole | F5: Bourse | G5: Industrie | H5: Catégorie | I5: Devise | J5: Nb d'actions | K5: Coût moyen | L5: Coût total | M5: Prix actuel | N5: Valeur au marché ($ local) | O5: Valeur au marché (CAD) | P5: Variation du jour ($) | Q5: Variation du jour (%) | R5: Gain non réalisé ($) | S5: Gain non réalisé (%) | T5: Dividende trimestriel | U5: Dividende annuel | V5: Revenu annuel anticipé | W5: Rendement des dividendes | X5: $ de dividendes par $ investi | Y5: Croissance (années) | Z5: Retour total | AA5: Total - dividendes reçus | AB5: Janvier 2019 | AC5: Février 2019 | AD5: Mars 2019 | AE5: Avril 2019 | AF5: Mai 2019 | AG5: Juin 2019 | AH5: Juillet 2019 | AI5: Août 2019 | AJ5: Septembre 2019 | AK5: Octobre 2019 | AL5: Novembre 2019 | AM5: Décembre 2019 | AN5: Janvier 2020 | AO5: Février 2020 | AP5: Mars 2020 | AQ5: Avril 2020 | AR5: Mai 2020 | AS5: Juin 2020 | AT5: Juillet 2020 | AU5: Août 2020 | AV5: Septembre 2020 | AW5: Octobre 2020 | AX5: Novembre 2020 | AY5: Décembre 2020 | AZ5: Janvier 2021 | BA5: Février 2021 | BB5: Mars 2021 | BC5: Avril 2021 | BD5: Mai 2021 | BE5: Juin 2021 | BF5: Juillet 2021 | BG5: Août 2021 | BH5: Septembre 2021 | BI5: Octobre 2021 | BJ5: Novembre 2021 | BK5: Décembre 2021 | BL5: Janvier 2022 | BM5: Février 2022 | BN5: Mars 2022 | BO5: Avril 2022 | BP5: Mai 2022 | BQ5: Juin 2022 | BR5: Juillet 2022 | BS5: Août 2022 | BT5: Septembre 2022 | BU5: Octobre 2022 | BV5: Novembre 2022 | BW5: Décembre 2022 | BX5: Janvier 2023 | BY5: Février 2023 | BZ5: Mars 2023 | CA5: Avril 2023 | CB5: Mai 2023 | CC5: .Juin 2023 | CD5: Juillet 2023 | CE5: Août 2023 | CF5: Septembre 2023 | CG5: Octobre 2023 | CH5: Novembre 2023 | CI5: Décembre 2023 | CJ5: Janvier 2024 | CK5: Février 2024 | CL5: Mars 2024 | CM5: Avril 2024 | CN5: Mai 2024 | CO5: Juin 2024 | CP5: Juillet 2024 | CQ5: Août 2024 | CR5: Septembre 2024 | CS5: Octobre 2024 | CT5: Novembre 2024 | CU5: Décembre 2024 | CV5: Janvier 2025 | CW5: Février 2025 | CX5: Mars 2025 | CY5: Avril 2025 | CZ5: Mai 2025 | DA5: Juin 2025 | DB5: Juillet 2025 | DC5: Août 2025 | DD5: Septembre 2025 | DE5: Octobre 2025 | DF5: Novembre 2025 | DG5: Décembre 2025 | DH5: Janvier 2026 | DI5: Février 2026
B6: =IF(C6="","",_xlfn.XLOOKUP(C6,Type_Compte,Num_Compte)) -> 20K6HU7 | C6: REER (USD) | D6: #VALUE! | E6: {=_FV(Titres[[#This Row],[Action]],"Code mnémonique",TRUE)} -> MMM | F6: {=_FV(D6,"Change")} -> New York Stock Exchange | G6: {=IFERROR(_FV(Titres[[#This Row],[Action]],"Industrie"),"")} -> Consumer Goods Conglomerates | H6: Actions américaines | I6: {=_FV(D6,"Devise")} -> USD | J6: 30 | K6: 89.96 | L6: =J6*K6 -> 2698.8 | M6: {=_FV(D6,"Prix")} -> 148.48 | N6: =J6*M6 -> 4454.4 | O6: =IF(Titres[[#This Row],[Devise]]="CAD",Titres[[#This Row],[Valeur au marché ($ local)]],Titres[[#This Row],[Valeur au marché ($ local)]]*Ressources!$I$3) -> 6084.7104 | P6: {=(Titres[[#This Row],[Prix actuel]]-_FV(Titres[[#This Row],[Action]],"Clôture précédente",TRUE))*Titres[[#This Row],[Nb d''actions]]} -> -87.6 | Q6: =Titres[[#This Row],[Variation du jour ($)]]/(Titres[[#This Row],[Valeur au marché ($ local)]]-Titres[[#This Row],[Variation du jour ($)]]) -> -0.019286658 | R6: =Titres[[#This Row],[Valeur au marché ($ local)]]-Titres[[#This Row],[Coût total]] -> 1755.6 | S6: =Titres[[#This Row],[Gain non réalisé ($)]]/Titres[[#This Row],[Coût total]] -> 0.65051134 | T6: 0.78 | U6: =4*Titres[[#This Row],[Dividende trimestriel]] -> 3.12 | V6: =Titres[[#This Row],[Dividende annuel]]*Titres[[#This Row],[Nb d''actions]] -> 93.6 | W6: =Titres[[#This Row],[Dividende annuel]]/Titres[[#This Row],[Prix actuel]] -> 0.021012931 | X6: =Titres[[#This Row],[Dividende annuel]]/Titres[[#This Row],[Coût moyen]] -> 0.034682081 | Y6: 64 | Z6: =(((Titres[[#This Row],[Valeur au marché ($ local)]]-Titres[[#This Row],[Coût total]])+Titres[[#This Row],[Total - dividendes reçus]])/Titres[[#This Row],[Coût total]]) -> 0.69979991 | AA6: =SUM(Titres[[#This Row],[Janvier 2019]:[Août 2024]]) -> 133.02 | CE6: =25.55-3.83 -> 21.72 | CI6: 45 | CL6: 45.3 | CO6: 21 | CR6: 21 | CU6: 21 | CX6: 21.9 | DA6: 21.9 | DD6: 21.9 | DG6: 21.9
B7: =IF(C7="","",_xlfn.XLOOKUP(C7,Type_Compte,Num_Compte)) -> 20K6HZ6 | C7: CELI (CAD) | D7: #VALUE! | E7: {=_FV(Titres[[#This Row],[Action]],"Code mnémonique",TRUE)} -> AQN | F7: {=_FV(D7,"Change")} -> Toronto Stock Exchange | G7: {=IFERROR(_FV(Titres[[#This Row],[Action]],"Industrie"),"")} -> Multiline Utilities | H7: Actions canadiennes | I7: {=_FV(D7,"Devise")} -> CAD | J7: 400 | K7: 11.48 | L7: =J7*K7 -> 4592 | M7: {=_FV(D7,"Prix")} -> 8.5 | N7: =J7*M7 -> 3400 | O7: =IF(Titres[[#This Row],[Devise]]="CAD",Titres[[#This Row],[Valeur au marché ($ local)]],Titres[[#This Row],[Valeur au marché ($ local)]]*Ressources!$I$3) -> 3400 | P7: {=(Titres[[#This Row],[Prix actuel]]-_FV(Titres[[#This Row],[Action]],"Clôture précédente",TRUE))*Titres[[#This Row],[Nb d''actions]]} -> -48 | Q7: =Titres[[#This Row],[Variation du jour ($)]]/(Titres[[#This Row],[Valeur au marché ($ local)]]-Titres[[#This Row],[Variation du jour ($)]]) -> -0.013921114 | R7: =Titres[[#This Row],[Valeur au marché ($ local)]]-Titres[[#This Row],[Coût total]] -> -1192 | S7: =Titres[[#This Row],[Gain non réalisé ($)]]/Titres[[#This Row],[Coût total]] -> -0.25958188 | T7: 0.092 | U7: =4*Titres[[#This Row],[Dividende trimestriel]] -> 0.368 | V7: =Titres[[#This Row],[Dividende annuel]]*Titres[[#This Row],[Nb d''actions]] -> 147.2 | W7: =Titres[[#This Row],[Dividende annuel]]/Titres[[#This Row],[Prix actuel]] -> 0.043294118 | X7: =Titres[[#This Row],[Dividende annuel]]/Titres[[#This Row],[Coût moyen]] -> 0.032055749 | Y7: 10 | Z7: =(((Titres[[#This Row],[Valeur au marché ($ local)]]-Titres[[#This Row],[Coût total]])+Titres[[#This Row],[Total - dividendes reçus]])/Titres[[#This Row],[Coût total]]) -> -0.080060976 | AA7: =SUM(Titres[[#This Row],[Janvier 2019]:[Août 2024]]) -> 824.36 | AH7: 34.38 | AK7: 35.69 | AN7: 35.31 | AQ7: 35.65 | AT7: 41.62 | AW7: 39.06 | AZ7: 38.36 | BC7: 37.22 | BF7: 39.78 | BI7: 40.54 | BL7: 40.36 | BO7: 41.06 | BR7: 44.56 | BU7: 43.93 | BX7: 46.31 | CA7: 28.4 | CD7: 27.6 | CG7: 27.74 | CJ7: 28.44 | CM7: 58.74 | CP7: 59.61 | CS7: 35.72 | CV7: 36.02 | CY7: 37.36 | DB7: 35.87 | DE7: 35.74 | DH7: 36.71
B8: =IF(C8="","",_xlfn.XLOOKUP(C8,Type_Compte,Num_Compte)) -> 20K6HZ6 | C8: CELI (CAD) | D8: #VALUE! | E8: {=_FV(Titres[[#This Row],[Action]],"Code mnémonique",TRUE)} -> ALA | F8: {=_FV(D8,"Change")} -> Toronto Stock Exchange | G8: {=IFERROR(_FV(Titres[[#This Row],[Action]],"Industrie"),"")} -> Natural Gas Utilities | H8: Actions canadiennes | I8: {=_FV(D8,"Devise")} -> CAD | J8: 90 | K8: 29.14 | L8: =J8*K8 -> 2622.6 | M8: {=_FV(D8,"Prix")} -> 48.82 | N8: =J8*M8 -> 4393.8 | O8: =IF(Titres[[#This Row],[Devise]]="CAD",Titres[[#This Row],[Valeur au marché ($ local)]],Titres[[#This Row],[Valeur au marché ($ local)]]*Ressources!$I$3) -> 4393.8 | P8: {=(Titres[[#This Row],[Prix actuel]]-_FV(Titres[[#This Row],[Action]],"Clôture précédente",TRUE))*Titres[[#This Row],[Nb d''actions]]} -> -37.8 | Q8: =Titres[[#This Row],[Variation du jour ($)]]/(Titres[[#This Row],[Valeur au marché ($ local)]]-Titres[[#This Row],[Variation du jour ($)]]) -> -0.0085296507 | R8: =Titres[[#This Row],[Valeur au marché ($ local)]]-Titres[[#This Row],[Coût total]] -> 1771.2 | S8: =Titres[[#This Row],[Gain non réalisé ($)]]/Titres[[#This Row],[Coût total]] -> 0.67536033 | T8: 0.334 | U8: =4*Titres[[#This Row],[Dividende trimestriel]] -> 1.336 | V8: =Titres[[#This Row],[Dividende annuel]]*Titres[[#This Row],[Nb d''actions]] -> 120.24 | W8: =Titres[[#This Row],[Dividende annuel]]/Titres[[#This Row],[Prix actuel]] -> 0.027365834 | X8: =Titres[[#This Row],[Dividende annuel]]/Titres[[#This Row],[Coût moyen]] -> 0.045847632 | Y8: 0 | Z8: =(((Titres[[#This Row],[Valeur au marché ($ local)]]-Titres[[#This Row],[Coût total]])+Titres[[#This Row],[Total - dividendes reçus]])/Titres[[#This Row],[Coût total]]) -> 0.86405094 | AA8: =SUM(Titres[[#This Row],[Janvier 2019]:[Août 2024]]) -> 494.86 | AB8: 7.2 | AC8: 7.2 | AD8: 7.2 | AE8: 7.2 | AF8: 7.2 | AG8: 7.2 | AH8: 7.2 | AI8: 7.2 | AJ8: 7.2 | AK8: 7.2 | AL8: 7.2 | AM8: 7.2 | AN8: 7.2 | AO8: 7.2 | AP8: 7.2 | AQ8: 7.2 | AR8: 7.2 | AS8: 7.2 | AT8: 7.2 | AU8: 7.2 | AV8: 7.2 | AW8: 7.2 | AX8: 7.2 | AY8: 7.2 | AZ8: 7.5 | BA8: 7.5 | BB8: 7.5 | BC8: 7.5 | BD8: 7.5 | BE8: 7.5 | BF8: 7.5 | BG8: 7.5 | BH8: 7.5 | BI8: 7.5 | BJ8: 7.5 | BK8: 15 | BN8: 23.85 | BQ8: 23.85 | BT8: 23.85 | BW8: 23.85 | CC8: 25.2 | CF8: 25.2 | CI8: 25.2 | CL8: 26.78 | CP8: 26.78 | CR8: 26.78 | CU8: 26.78 | CX8: 28.35 | DA8: 28.35 | DD8: 28.35 | DG8: 28.35
B9: =IF(C9="","",_xlfn.XLOOKUP(C9,Type_Compte,Num_Compte)) -> 20K6HU7 | C9: REER (USD) | D9: #VALUE! | E9: {=_FV(Titres[[#This Row],[Action]],"Code mnémonique",TRUE)} -> MO | F9: {=_FV(D9,"Change")} -> New York Stock Exchange | G9: {=IFERROR(_FV(Titres[[#This Row],[Action]],"Industrie"),"")} -> Food & Tobacco | H9: Actions américaines | I9: {=_FV(D9,"Devise")} -> USD | J9: 65 | K9: 50.26 | L9: =J9*K9 -> 3266.9 | M9: {=_FV(D9,"Prix")} -> 64.67 | N9: =J9*M9 -> 4203.55 | O9: =IF(Titres[[#This Row],[Devise]]="CAD",Titres[[#This Row],[Valeur au marché ($ local)]],Titres[[#This Row],[Valeur au marché ($ local)]]*Ressources!$I$3) -> 5742.0493 | P9: {=(Titres[[#This Row],[Prix actuel]]-_FV(Titres[[#This Row],[Action]],"Clôture précédente",TRUE))*Titres[[#This Row],[Nb d''actions]]} -> 3.9 | Q9: =Titres[[#This Row],[Variation du jour ($)]]/(Titres[[#This Row],[Valeur au marché ($ local)]]-Titres[[#This Row],[Variation du jour ($)]]) -> 0.00092864882 | R9: =Titres[[#This Row],[Valeur au marché ($ local)]]-Titres[[#This Row],[Coût total]] -> 936.65 | S9: =Titres[[#This Row],[Gain non réalisé ($)]]/Titres[[#This Row],[Coût total]] -> 0.28670911 | T9: 1.06 | U9: =4*Titres[[#This Row],[Dividende trimestriel]] -> 4.24 | V9: =Titres[[#This Row],[Dividende annuel]]*Titres[[#This Row],[Nb d''actions]] -> 275.6 | W9: =Titres[[#This Row],[Dividende annuel]]/Titres[[#This Row],[Prix actuel]] -> 0.065563631 | X9: =Titres[[#This Row],[Dividende annuel]]/Titres[[#This Row],[Coût moyen]] -> 0.084361321 | Y9: 53 | Z9: =(((Titres[[#This Row],[Valeur au marché ($ local)]]-Titres[[#This Row],[Coût total]])+Titres[[#This Row],[Total - dividendes reçus]])/Titres[[#This Row],[Coût total]]) -> 0.61301234 | AA9: =SUM(Titres[[#This Row],[Janvier 2019]:[Août 2024]]) -> 1066 | AQ9: 54.6 | AT9: 54.6 | AW9: 55.9 | AZ9: 55.9 | BC9: 55.9 | BF9: 55.9 | BI9: 58.5 | BL9: 58.5 | BO9: 58.5 | BR9: 58.5 | BU9: 61.1 | BX9: 61.1 | CA9: 61.1 | CD9: 61.1 | CG9: 63.7 | CJ9: 63.7 | CM9: 63.7 | CP9: 63.7 | CS9: 66.3 | CV9: 66.3 | CY9: 66.3 | DB9: 66.3 | DE9: 68.9 | DH9: 68.9
B10: =IF(C10="","",_xlfn.XLOOKUP(C10,Type_Compte,Num_Compte)) -> 20K6HU7 | C10: REER (USD) | D10: #VALUE! | E10: {=_FV(Titres[[#This Row],[Action]],"Code mnémonique",TRUE)} -> T | F10: {=_FV(D10,"Change")} -> New York Stock Exchange | G10: {=IFERROR(_FV(Titres[[#This Row],[Action]],"Industrie"),"")} -> Telecommunications Services | H10: Actions américaines | I10: {=_FV(D10,"Devise")} -> USD | J10: 124 | K10: 24.44 | L10: =J10*K10 -> 3030.56 | M10: {=_FV(D10,"Prix")} -> 25.88 | N10: =J10*M10 -> 3209.12 | O10: =IF(Titres[[#This Row],[Devise]]="CAD",Titres[[#This Row],[Valeur au marché ($ local)]],Titres[[#This Row],[Valeur au marché ($ local)]]*Ressources!$I$3) -> 4383.6579 | P10: {=(Titres[[#This Row],[Prix actuel]]-_FV(Titres[[#This Row],[Action]],"Clôture précédente",TRUE))*Titres[[#This Row],[Nb d''actions]]} -> -37.2 | Q10: =Titres[[#This Row],[Variation du jour ($)]]/(Titres[[#This Row],[Valeur au marché ($ local)]]-Titres[[#This Row],[Variation du jour ($)]]) -> -0.011459129 | R10: =Titres[[#This Row],[Valeur au marché ($ local)]]-Titres[[#This Row],[Coût total]] -> 178.56 | S10: =Titres[[#This Row],[Gain non réalisé ($)]]/Titres[[#This Row],[Coût total]] -> 0.058919804 | T10: 0.278 | U10: =4*Titres[[#This Row],[Dividende trimestriel]] -> 1.112 | V10: =Titres[[#This Row],[Dividende annuel]]*Titres[[#This Row],[Nb d''actions]] -> 137.888 | W10: =Titres[[#This Row],[Dividende annuel]]/Titres[[#This Row],[Prix actuel]] -> 0.042967543 | X10: =Titres[[#This Row],[Dividende annuel]]/Titres[[#This Row],[Coût moyen]] -> 0.045499182 | Y10: 0 | Z10: =(((Titres[[#This Row],[Valeur au marché ($ local)]]-Titres[[#This Row],[Coût total]])+Titres[[#This Row],[Total - dividendes reçus]])/Titres[[#This Row],[Coût total]]) -> 0.19677551 | AA10: =SUM(Titres[[#This Row],[Janvier 2019]:[Août 2024]]) -> 417.78 | AC10: 22.44 | AF10: 22.44 | AI10: 22.44 | AL10: 22.44 | AO10: 22.88 | AR10: 22.88 | AU10: 22.88 | AX10: 22.88 | BA10: 22.88 | BD10: 22.88 | BG10: 22.88 | BJ10: 22.88 | BM10: 22.88 | BP10: 12.21 | BS10: 12.21 | BV10: 12.21 | BY10: 12.21 | CB10: 12.21 | CE10: 12.21 | CH10: 12.21 | CK10: 12.21 | CN10: 12.21 | CQ10: 12.21 | CT10: 34.41 | CW10: 34.41 | CZ10: 34.41 | DC10: 34.41 | DF10: 34.41 | DI10: 34.41
B11: =IF(C11="","",_xlfn.XLOOKUP(C11,Type_Compte,Num_Compte)) -> 20K6HU7 | C11: REER (USD) | D11: #VALUE! | E11: {=_FV(Titres[[#This Row],[Action]],"Code mnémonique",TRUE)} -> BAC | F11: {=_FV(D11,"Change")} -> New York Stock Exchange | G11: {=IFERROR(_FV(Titres[[#This Row],[Action]],"Industrie"),"")} -> Banking Services | H11: Actions américaines | I11: {=_FV(D11,"Devise")} -> USD | J11: 150 | K11: 48.57 | L11: =J11*K11 -> 7285.5 | M11: {=_FV(D11,"Prix")} -> 53.465 | N11: =J11*M11 -> 8019.75 | O11: =IF(Titres[[#This Row],[Devise]]="CAD",Titres[[#This Row],[Valeur au marché ($ local)]],Titres[[#This Row],[Valeur au marché ($ local)]]*Ressources!$I$3) -> 10954.979 | P11: {=(Titres[[#This Row],[Prix actuel]]-_FV(Titres[[#This Row],[Action]],"Clôture précédente",TRUE))*Titres[[#This Row],[Nb d''actions]]} -> -72.75 | Q11: =Titres[[#This Row],[Variation du jour ($)]]/(Titres[[#This Row],[Valeur au marché ($ local)]]-Titres[[#This Row],[Variation du jour ($)]]) -> -0.0089898054 | R11: =Titres[[#This Row],[Valeur au marché ($ local)]]-Titres[[#This Row],[Coût total]] -> 734.25 | S11: =Titres[[#This Row],[Gain non réalisé ($)]]/Titres[[#This Row],[Coût total]] -> 0.10078238 | T11: 0.28 | U11: =4*Titres[[#This Row],[Dividende trimestriel]] -> 1.12 | V11: =Titres[[#This Row],[Dividende annuel]]*Titres[[#This Row],[Nb d''actions]] -> 168 | W11: =Titres[[#This Row],[Dividende annuel]]/Titres[[#This Row],[Prix actuel]] -> 0.020948284 | X11: =Titres[[#This Row],[Dividende annuel]]/Titres[[#This Row],[Coût moyen]] -> 0.023059502 | Y11: 9 | Z11: =(((Titres[[#This Row],[Valeur au marché ($ local)]]-Titres[[#This Row],[Coût total]])+Titres[[#This Row],[Total - dividendes reçus]])/Titres[[#This Row],[Coût total]]) -> 0.14278361 | AA11: =SUM(Titres[[#This Row],[Janvier 2019]:[Août 2024]]) -> 306 | BN11: 31.5 | BQ11: 31.5 | BT11: 33 | BW11: 33 | CC11: 33 | CF11: 36 | CI11: 36 | CL11: 36 | CP11: 36 | CR11: 39 | CU11: 39 | CX11: 39 | DA11: 39 | DD11: 42 | DG11: 42
B12: =IF(C12="","",_xlfn.XLOOKUP(C12,Type_Compte,Num_Compte)) -> 20K6HZ6 | C12: CELI (CAD) | D12: #VALUE! | E12: {=_FV(Titres[[#This Row],[Action]],"Code mnémonique",TRUE)} -> CM | F12: {=_FV(D12,"Change")} -> Toronto Stock Exchange | G12: {=IFERROR(_FV(Titres[[#This Row],[Action]],"Industrie"),"")} -> Banking Services | H12: Actions canadiennes | I12: {=_FV(D12,"Devise")} -> CAD | J12: 88 | K12: 52.81 | L12: =J12*K12 -> 4647.28 | M12: {=_FV(D12,"Prix")} -> 148.48 | N12: =J12*M12 -> 13066.24 | O12: =IF(Titres[[#This Row],[Devise]]="CAD",Titres[[#This Row],[Valeur au marché ($ local)]],Titres[[#This Row],[Valeur au marché ($ local)]]*Ressources!$I$3) -> 13066.24 | P12: {=(Titres[[#This Row],[Prix actuel]]-_FV(Titres[[#This Row],[Action]],"Clôture précédente",TRUE))*Titres[[#This Row],[Nb d''actions]]} -> -168.08 | Q12: =Titres[[#This Row],[Variation du jour ($)]]/(Titres[[#This Row],[Valeur au marché ($ local)]]-Titres[[#This Row],[Variation du jour ($)]]) -> -0.012700313 | R12: =Titres[[#This Row],[Valeur au marché ($ local)]]-Titres[[#This Row],[Coût total]] -> 8418.96 | S12: =Titres[[#This Row],[Gain non réalisé ($)]]/Titres[[#This Row],[Coût total]] -> 1.8115887 | T12: 1.07 | U12: =4*Titres[[#This Row],[Dividende trimestriel]] -> 4.28 | V12: =Titres[[#This Row],[Dividende annuel]]*Titres[[#This Row],[Nb d''actions]] -> 376.64 | W12: =Titres[[#This Row],[Dividende annuel]]/Titres[[#This Row],[Prix actuel]] -> 0.028825431 | X12: =Titres[[#This Row],[Dividende annuel]]/Titres[[#This Row],[Coût moyen]] -> 0.081045257 | Y12: 0 | Z12: =(((Titres[[#This Row],[Valeur au marché ($ local)]]-Titres[[#This Row],[Coût total]])+Titres[[#This Row],[Total - dividendes reçus]])/Titres[[#This Row],[Coût total]]) -> 2.0794701 | AA12: =SUM(Titres[[#This Row],[Janvier 2019]:[Août 2024]]) -> 1244.92 | AB12: 19.04 | AE12: 19.6 | AH12: 19.6 | AK12: 20.16 | AN12: 20.16 | AQ12: 20.44 | AT12: 20.44 | AW12: 20.44 | AZ12: 64.24 | BC12: 64.24 | BF12: 64.24 | BI12: 64.24 | BL12: 70.84 | BO12: 70.84 | BR12: 73.04 | BU12: 73.04 | BX12: 74.8 | CA12: 74.8 | CD12: 76.56 | CG12: 76.56 | CJ12: 79.2 | CM12: 79.2 | CP12: 79.2 | CS12: 79.2 | CV12: 85.36 | CY12: 85.36 | DB12: 85.36 | DE12: 85.36 | DH12: 94.16
B13: =IF(C13="","",_xlfn.XLOOKUP(C13,Type_Compte,Num_Compte)) -> 20K6HZ6 | C13: CELI (CAD) | D13: #VALUE! | E13: {=_FV(Titres[[#This Row],[Action]],"Code mnémonique",TRUE)} -> BMO | F13: {=_FV(D13,"Change")} -> Toronto Stock Exchange | G13: {=IFERROR(_FV(Titres[[#This Row],[Action]],"Industrie"),"")} -> Banking Services | H13: Actions canadiennes | I13: {=_FV(D13,"Devise")} -> CAD | J13: 65 | K13: 127.78 | L13: =J13*K13 -> 8305.7 | M13: {=_FV(D13,"Prix")} -> 207.25 | N13: =J13*M13 -> 13471.25 | O13: =IF(Titres[[#This Row],[Devise]]="CAD",Titres[[#This Row],[Valeur au marché ($ local)]],Titres[[#This Row],[Valeur au marché ($ local)]]*Ressources!$I$3) -> 13471.25 | P13: {=(Titres[[#This Row],[Prix actuel]]-_FV(Titres[[#This Row],[Action]],"Clôture précédente",TRUE))*Titres[[#This Row],[Nb d''actions]]} -> -153.4 | Q13: =Titres[[#This Row],[Variation du jour ($)]]/(Titres[[#This Row],[Valeur au marché ($ local)]]-Titres[[#This Row],[Variation du jour ($)]]) -> -0.011259005 | R13: =Titres[[#This Row],[Valeur au marché ($ local)]]-Titres[[#This Row],[Coût total]] -> 5165.55 | S13: =Titres[[#This Row],[Gain non réalisé ($)]]/Titres[[#This Row],[Coût total]] -> 0.62192831 | T13: 1.67 | U13: =4*Titres[[#This Row],[Dividende trimestriel]] -> 6.68 | V13: =Titres[[#This Row],[Dividende annuel]]*Titres[[#This Row],[Nb d''actions]] -> 434.2 | W13: =Titres[[#This Row],[Dividende annuel]]/Titres[[#This Row],[Prix actuel]] -> 0.032231604 | X13: =Titres[[#This Row],[Dividende annuel]]/Titres[[#This Row],[Coût moyen]] -> 0.052277352 | Y13: 1 | Z13: =(((Titres[[#This Row],[Valeur au marché ($ local)]]-Titres[[#This Row],[Coût total]])+Titres[[#This Row],[Total - dividendes reçus]])/Titres[[#This Row],[Coût total]]) -> 0.7168872 | AA13: =SUM(Titres[[#This Row],[Janvier 2019]:[Août 2024]]) -> 788.7 | AF13: 30 | AI13: 30.9 | AL13: 30.9 | AO13: 31.8 | AR13: 31.8 | AU13: 31.8 | BA13: 31.8 | BD13: 31.8 | BG13: 31.8 | BJ13: 31.8 | BM13: 39.9 | BP13: 39.9 | BS13: 41.7 | BV13: 41.7 | BY13: 42.9 | CB13: 42.9 | CE13: 44.1 | CH13: 44.1 | CK13: 45.3 | CN13: 45.3 | CQ13: 46.5 | CT13: 46.5 | CW13: 47.7 | CZ13: 103.35 | DC13: 105.95 | DF13: 105.95 | DI13: 108.55
B14: =IF(C14="","",_xlfn.XLOOKUP(C14,Type_Compte,Num_Compte)) -> 20K6HZ6 | C14: CELI (CAD) | D14: #VALUE! | E14: {=_FV(Titres[[#This Row],[Action]],"Code mnémonique",TRUE)} -> NA | F14: {=_FV(D14,"Change")} -> Toronto Stock Exchange | G14: {=IFERROR(_FV(Titres[[#This Row],[Action]],"Industrie"),"")} -> Banking Services | H14: Actions canadiennes | I14: {=_FV(D14,"Devise")} -> CAD | J14: 81 | K14: 69.48 | L14: =J14*K14 -> 5627.88 | M14: {=_FV(D14,"Prix")} -> 201.79 | N14: =J14*M14 -> 16344.99 | O14: =IF(Titres[[#This Row],[Devise]]="CAD",Titres[[#This Row],[Valeur au marché ($ local)]],Titres[[#This Row],[Valeur au marché ($ local)]]*Ressources!$I$3) -> 16344.99 | P14: {=(Titres[[#This Row],[Prix actuel]]-_FV(Titres[[#This Row],[Action]],"Clôture précédente",TRUE))*Titres[[#This Row],[Nb d''actions]]} -> -153.09 | Q14: =Titres[[#This Row],[Variation du jour ($)]]/(Titres[[#This Row],[Valeur au marché ($ local)]]-Titres[[#This Row],[Variation du jour ($)]]) -> -0.0092792616 | R14: =Titres[[#This Row],[Valeur au marché ($ local)]]-Titres[[#This Row],[Coût total]] -> 10717.11 | S14: =Titres[[#This Row],[Gain non réalisé ($)]]/Titres[[#This Row],[Coût total]] -> 1.904289 | T14: 1.24 | U14: =4*Titres[[#This Row],[Dividende trimestriel]] -> 4.96 | V14: =Titres[[#This Row],[Dividende annuel]]*Titres[[#This Row],[Nb d''actions]] -> 401.76 | W14: =Titres[[#This Row],[Dividende annuel]]/Titres[[#This Row],[Prix actuel]] -> 0.024580009 | X14: =Titres[[#This Row],[Dividende annuel]]/Titres[[#This Row],[Coût moyen]] -> 0.07138745 | Y14: 8 | Z14: =(((Titres[[#This Row],[Valeur au marché ($ local)]]-Titres[[#This Row],[Coût total]])+Titres[[#This Row],[Total - dividendes reçus]])/Titres[[#This Row],[Coût total]]) -> 2.0401839 | AA14: =SUM(Titres[[#This Row],[Janvier 2019]:[Août 2024]]) -> 764.8 | AC14: 26 | AF14: 26 | AI14: 27.2 | AL14: 27.2 | AO14: 28.4 | AR14: 28.4 | AU14: 28.4 | AX14: 28.4 | BA14: 28.4 | BD14: 28.4 | BG14: 28.4 | BJ14: 28.4 | BM14: 34.8 | BP14: 34.8 | BS14: 36.8 | BV14: 36.8 | BY14: 38.8 | CB14: 38.8 | CE14: 40.8 | CH14: 40.8 | CK14: 42.4 | CN14: 42.4 | CQ14: 44 | CT14: 44 | CW14: 45.6 | CZ14: 92.34 | DC14: 95.58 | DF14: 95.58 | DI14: 100.44
B15: =IF(C15="","",_xlfn.XLOOKUP(C15,Type_Compte,Num_Compte)) -> 20K6HZ6 | C15: CELI (CAD) | D15: Canadian Western Bank (merge avec Banque Nationale) | E15: CWB | G15: {=IFERROR(_FV(Titres[[#This Row],[Action]],"Industrie"),"")} | H15: Actions canadiennes | J15: 0 | K15: 32.39 | L15: =J15*K15 -> 0 | N15: =J15*M15 -> 0 | O15: =IF(Titres[[#This Row],[Devise]]="CAD",Titres[[#This Row],[Valeur au marché ($ local)]],Titres[[#This Row],[Valeur au marché ($ local)]]*Ressources!$I$3) -> 0 | Q15: =Titres[[#This Row],[Variation du jour ($)]]/(Titres[[#This Row],[Valeur au marché ($ local)]]-Titres[[#This Row],[Variation du jour ($)]]) -> #DIV/0! | R15: =Titres[[#This Row],[Valeur au marché ($ local)]]-Titres[[#This Row],[Coût total]] -> 0 | S15: =Titres[[#This Row],[Gain non réalisé ($)]]/Titres[[#This Row],[Coût total]] -> #DIV/0! | T15: 0.35 | U15: =4*Titres[[#This Row],[Dividende trimestriel]] -> 1.4 | V15: =Titres[[#This Row],[Dividende annuel]]*Titres[[#This Row],[Nb d''actions]] -> 0 | W15: =Titres[[#This Row],[Dividende annuel]]/Titres[[#This Row],[Prix actuel]] -> #DIV/0! | X15: =Titres[[#This Row],[Dividende annuel]]/Titres[[#This Row],[Coût moyen]] -> 0.043223217 | Y15: 15 | Z15: =(((Titres[[#This Row],[Valeur au marché ($ local)]]-Titres[[#This Row],[Coût total]])+Titres[[#This Row],[Total - dividendes reçus]])/Titres[[#This Row],[Coût total]]) -> #DIV/0! | AA15: =SUM(Titres[[#This Row],[Janvier 2019]:[Août 2024]]) -> 645.42 | AB15: 24.18 | AD15: 25.11 | AG15: 25.11 | AJ15: 26.04 | AN15: 26.04 | AP15: 26.97 | AS15: 26.97 | AV15: 26.97 | AZ15: 26.97 | BB15: 26.97 | BE15: 26.97 | BH15: 26.97 | BL15: 27.9 | BN15: 27.9 | BQ15: 28.83 | BT15: 28.83 | BX15: 29.76 | BZ15: 29.76 | CC15: 30.69 | CF15: 30.69 | CJ15: 31.62 | CL15: 31.62 | CO15: 32.55 | CR15: 32.55 | CV15: 33.48
B16: =IF(C16="","",_xlfn.XLOOKUP(C16,Type_Compte,Num_Compte)) -> 20K6HZ6 | C16: CELI (CAD) | D16: #VALUE! | E16: {=_FV(Titres[[#This Row],[Action]],"Code mnémonique",TRUE)} -> RY | F16: {=_FV(D16,"Change")} -> Toronto Stock Exchange | G16: {=IFERROR(_FV(Titres[[#This Row],[Action]],"Industrie"),"")} -> Banking Services | H16: Actions canadiennes | I16: {=_FV(D16,"Devise")} -> CAD | J16: 55 | K16: 95.04 | L16: =J16*K16 -> 5227.2 | M16: {=_FV(D16,"Prix")} -> 242.81 | N16: =J16*M16 -> 13354.55 | O16: =IF(Titres[[#This Row],[Devise]]="CAD",Titres[[#This Row],[Valeur au marché ($ local)]],Titres[[#This Row],[Valeur au marché ($ local)]]*Ressources!$I$3) -> 13354.55 | P16: {=(Titres[[#This Row],[Prix actuel]]-_FV(Titres[[#This Row],[Action]],"Clôture précédente",TRUE))*Titres[[#This Row],[Nb d''actions]]} -> -167.2 | Q16: =Titres[[#This Row],[Variation du jour ($)]]/(Titres[[#This Row],[Valeur au marché ($ local)]]-Titres[[#This Row],[Variation du jour ($)]]) -> -0.012365263 | R16: =Titres[[#This Row],[Valeur au marché ($ local)]]-Titres[[#This Row],[Coût total]] -> 8127.35 | S16: =Titres[[#This Row],[Gain non réalisé ($)]]/Titres[[#This Row],[Coût total]] -> 1.554819 | T16: 1.64 | U16: =4*Titres[[#This Row],[Dividende trimestriel]] -> 6.56 | V16: =Titres[[#This Row],[Dividende annuel]]*Titres[[#This Row],[Nb d''actions]] -> 360.8 | W16: =Titres[[#This Row],[Dividende annuel]]/Titres[[#This Row],[Prix actuel]] -> 0.027017009 | X16: =Titres[[#This Row],[Dividende annuel]]/Titres[[#This Row],[Coût moyen]] -> 0.069023569 | Y16: 12 | Z16: =(((Titres[[#This Row],[Valeur au marché ($ local)]]-Titres[[#This Row],[Coût total]])+Titres[[#This Row],[Total - dividendes reçus]])/Titres[[#This Row],[Coût total]]) -> 1.784617 | AA16: =SUM(Titres[[#This Row],[Janvier 2019]:[Août 2024]]) -> 1201.2 | AC16: 19.6 | AF16: 20.4 | AI16: 20.4 | AL16: 21 | AO16: 21 | AR16: 21.6 | AU16: 21.6 | AX16: 21.6 | BA16: 59.4 | BD16: 59.4 | BG16: 59.4 | BJ16: 59.4 | BM16: 66 | BP16: 66 | BS16: 70.4 | BV16: 70.4 | BY16: 72.6 | CB16: 72.6 | CE16: 74.25 | CH16: 74.25 | CK16: 75.9 | CN16: 75.9 | CQ16: 78.1 | CT16: 78.1 | CW16: 81.4 | CZ16: 81.4 | DC16: 84.7 | DF16: 84.7 | DI16: 90.2
B17: =IF(C17="","",_xlfn.XLOOKUP(C17,Type_Compte,Num_Compte)) -> 20K6HZ6 | C17: CELI (CAD) | D17: #VALUE! | E17: {=_FV(Titres[[#This Row],[Action]],"Code mnémonique",TRUE)} -> BEP.UN | F17: {=_FV(D17,"Change")} -> Toronto Stock Exchange | G17: {=IFERROR(_FV(Titres[[#This Row],[Action]],"Industrie"),"")} | H17: Actions canadiennes | I17: {=_FV(D17,"Devise")} -> CAD | J17: 180 | K17: 38.81 | L17: =J17*K17 -> 6985.8 | M17: {=_FV(D17,"Prix")} -> 44.35 | N17: =J17*M17 -> 7983 | O17: =IF(Titres[[#This Row],[Devise]]="CAD",Titres[[#This Row],[Valeur au marché ($ local)]],Titres[[#This Row],[Valeur au marché ($ local)]]*Ressources!$I$3) -> 7983 | P17: {=(Titres[[#This Row],[Prix actuel]]-_FV(Titres[[#This Row],[Action]],"Clôture précédente",TRUE))*Titres[[#This Row],[Nb d''actions]]} -> -541.8 | Q17: =Titres[[#This Row],[Variation du jour ($)]]/(Titres[[#This Row],[Valeur au marché ($ local)]]-Titres[[#This Row],[Variation du jour ($)]]) -> -0.063555743 | R17: =Titres[[#This Row],[Valeur au marché ($ local)]]-Titres[[#This Row],[Coût total]] -> 997.2 | S17: =Titres[[#This Row],[Gain non réalisé ($)]]/Titres[[#This Row],[Coût total]] -> 0.14274671 | T17: 0.392 | U17: =4*Titres[[#This Row],[Dividende trimestriel]] -> 1.568 | V17: =Titres[[#This Row],[Dividende annuel]]*Titres[[#This Row],[Nb d''actions]] -> 282.24 | W17: =Titres[[#This Row],[Dividende annuel]]/Titres[[#This Row],[Prix actuel]] -> 0.03535513 | X17: =Titres[[#This Row],[Dividende annuel]]/Titres[[#This Row],[Coût moyen]] -> 0.040401958 | Y17: 1 | Z17: =(((Titres[[#This Row],[Valeur au marché ($ local)]]-Titres[[#This Row],[Coût total]])+Titres[[#This Row],[Total - dividendes reçus]])/Titres[[#This Row],[Coût total]]) -> 0.2049028 | AA17: =SUM(Titres[[#This Row],[Janvier 2019]:[Août 2024]]) -> 434.21 | BN17: 40.63 | BQ17: 40.47 | BT17: 41.96 | BW17: 43.23 | CC17: 45.91 | CF17: 45.67 | CI17: 45.84 | CL17: 43.36 | CP17: 87.14 | CR17: 86.21 | CU17: 89.52 | CX17: 96.94 | DA17: 92.37 | DD17: 92.26 | DG17: 93.86
B18: =IF(C18="","",_xlfn.XLOOKUP(C18,Type_Compte,Num_Compte)) -> 20K6HU7 | C18: REER (USD) | D18: #VALUE! | E18: {=_FV(Titres[[#This Row],[Action]],"Code mnémonique",TRUE)} -> CVX | F18: {=_FV(D18,"Change")} -> New York Stock Exchange | G18: {=IFERROR(_FV(Titres[[#This Row],[Action]],"Industrie"),"")} -> Oil & Gas | H18: Actions américaines | I18: {=_FV(D18,"Devise")} -> USD | J18: 12 | K18: 105.7 | L18: =J18*K18 -> 1268.4 | M18: {=_FV(D18,"Prix")} -> 186.02 | N18: =J18*M18 -> 2232.24 | O18: =IF(Titres[[#This Row],[Devise]]="CAD",Titres[[#This Row],[Valeur au marché ($ local)]],Titres[[#This Row],[Valeur au marché ($ local)]]*Ressources!$I$3) -> 3049.2398 | P18: {=(Titres[[#This Row],[Prix actuel]]-_FV(Titres[[#This Row],[Action]],"Clôture précédente",TRUE))*Titres[[#This Row],[Nb d''actions]]} -> 33.24 | Q18: =Titres[[#This Row],[Variation du jour ($)]]/(Titres[[#This Row],[Valeur au marché ($ local)]]-Titres[[#This Row],[Variation du jour ($)]]) -> 0.015115962 | R18: =Titres[[#This Row],[Valeur au marché ($ local)]]-Titres[[#This Row],[Coût total]] -> 963.84 | S18: =Titres[[#This Row],[Gain non réalisé ($)]]/Titres[[#This Row],[Coût total]] -> 0.75988647 | T18: 1.78 | U18: =4*Titres[[#This Row],[Dividende trimestriel]] -> 7.12 | V18: =Titres[[#This Row],[Dividende annuel]]*Titres[[#This Row],[Nb d''actions]] -> 85.44 | W18: =Titres[[#This Row],[Dividende annuel]]/Titres[[#This Row],[Prix actuel]] -> 0.038275454 | X18: =Titres[[#This Row],[Dividende annuel]]/Titres[[#This Row],[Coût moyen]] -> 0.067360454 | Y18: 35 | Z18: =(((Titres[[#This Row],[Valeur au marché ($ local)]]-Titres[[#This Row],[Coût total]])+Titres[[#This Row],[Total - dividendes reçus]])/Titres[[#This Row],[Coût total]]) -> 1.0456954 | AA18: =SUM(Titres[[#This Row],[Janvier 2019]:[Août 2024]]) -> 362.52 | AD18: 14.28 | AG18: 14.28 | AJ18: 14.28 | AM18: 14.28 | AP18: 15.48 | AS18: 15.48 | AV18: 15.48 | AY18: 15.48 | BB18: 15.48 | BE18: 16.08 | BH18: 16.08 | BK18: 16.08 | BN18: 17.04 | BQ18: 17.04 | BT18: 17.04 | BW18: 17.04 | BZ18: 18.12 | CC18: 18.12 | CF18: 18.12 | CI18: 18.12 | CL18: 19.56 | CO18: 19.56 | CR18: 19.56 | CU18: 19.56 | CX18: 20.52 | DA18: 20.52 | DD18: 20.52 | DG18: 20.52
B19: =IF(C19="","",_xlfn.XLOOKUP(C19,Type_Compte,Num_Compte)) -> 20K6HU7 | C19: REER (USD) | D19: #VALUE! | E19: {=_FV(Titres[[#This Row],[Action]],"Code mnémonique",TRUE)} -> CL | F19: {=_FV(D19,"Change")} -> New York Stock Exchange | G19: {=IFERROR(_FV(Titres[[#This Row],[Action]],"Industrie"),"")} -> Personal & Household Products & Services | H19: Actions américaines | I19: {=_FV(D19,"Devise")} -> USD | J19: 23 | K19: 68.74 | L19: =J19*K19 -> 1581.02 | M19: {=_FV(D19,"Prix")} -> 81.81 | N19: =J19*M19 -> 1881.63 | O19: =IF(Titres[[#This Row],[Devise]]="CAD",Titres[[#This Row],[Valeur au marché ($ local)]],Titres[[#This Row],[Valeur au marché ($ local)]]*Ressources!$I$3) -> 2570.3066 | P19: {=(Titres[[#This Row],[Prix actuel]]-_FV(Titres[[#This Row],[Action]],"Clôture précédente",TRUE))*Titres[[#This Row],[Nb d''actions]]} -> -39.56 | Q19: =Titres[[#This Row],[Variation du jour ($)]]/(Titres[[#This Row],[Valeur au marché ($ local)]]-Titres[[#This Row],[Variation du jour ($)]]) -> -0.020591404 | R19: =Titres[[#This Row],[Valeur au marché ($ local)]]-Titres[[#This Row],[Coût total]] -> 300.61 | S19: =Titres[[#This Row],[Gain non réalisé ($)]]/Titres[[#This Row],[Coût total]] -> 0.19013675 | T19: 0.52 | U19: =4*Titres[[#This Row],[Dividende trimestriel]] -> 2.08 | V19: =Titres[[#This Row],[Dividende annuel]]*Titres[[#This Row],[Nb d''actions]] -> 47.84 | W19: =Titres[[#This Row],[Dividende annuel]]/Titres[[#This Row],[Prix actuel]] -> 0.025424765 | X19: =Titres[[#This Row],[Dividende annuel]]/Titres[[#This Row],[Coût moyen]] -> 0.030258947 | Y19: 59 | Z19: =(((Titres[[#This Row],[Valeur au marché ($ local)]]-Titres[[#This Row],[Coût total]])+Titres[[#This Row],[Total - dividendes reçus]])/Titres[[#This Row],[Coût total]]) -> 0.34288624 | AA19: =SUM(Titres[[#This Row],[Janvier 2019]:[Août 2024]]) -> 241.5 | AC19: 9.66 | AF19: 9.89 | AI19: 9.89 | AL19: 9.89 | AO19: 9.89 | AR19: 10.12 | AU19: 10.12 | AX19: 10.12 | BA19: 10.12 | BD19: 10.35 | BG19: 10.35 | BJ19: 10.35 | BM19: 10.35 | BP19: 10.81 | BS19: 10.81 | BV19: 10.81 | BY19: 10.81 | CB19: 11.04 | CE19: 11.04 | CH19: 11.04 | CK19: 11.04 | CN19: 11.5 | CQ19: 11.5 | CT19: 11.5 | CW19: 11.5 | CZ19: 11.96 | DC19: 11.96 | DF19: 11.96 | DI19: 11.96
B20: =IF(C20="","",_xlfn.XLOOKUP(C20,Type_Compte,Num_Compte)) -> 20K6HF2 | C20: Marge (USD) | D20: #VALUE! | E20: {=_FV(Titres[[#This Row],[Action]],"Code mnémonique",TRUE)} -> CMP | F20: {=_FV(D20,"Change")} -> New York Stock Exchange | G20: {=IFERROR(_FV(Titres[[#This Row],[Action]],"Industrie"),"")} -> Chemicals | H20: Actions américaines | I20: {=_FV(D20,"Devise")} -> USD | J20: 0 | K20: 46.48 | L20: =J20*K20 -> 0 | M20: {=_FV(D20,"Prix")} -> 25.55 | N20: =J20*M20 -> 0 | O20: =IF(Titres[[#This Row],[Devise]]="CAD",Titres[[#This Row],[Valeur au marché ($ local)]],Titres[[#This Row],[Valeur au marché ($ local)]]*Ressources!$I$3) -> 0 | P20: {=(Titres[[#This Row],[Prix actuel]]-_FV(Titres[[#This Row],[Action]],"Clôture précédente",TRUE))*Titres[[#This Row],[Nb d''actions]]} -> 0 | Q20: =Titres[[#This Row],[Variation du jour ($)]]/(Titres[[#This Row],[Valeur au marché ($ local)]]-Titres[[#This Row],[Variation du jour ($)]]) -> #DIV/0! | R20: =Titres[[#This Row],[Valeur au marché ($ local)]]-Titres[[#This Row],[Coût total]] -> 0 | S20: =Titres[[#This Row],[Gain non réalisé ($)]]/Titres[[#This Row],[Coût total]] -> #DIV/0! | T20: 0.15 | U20: =4*Titres[[#This Row],[Dividende trimestriel]] -> 0.6 | V20: =Titres[[#This Row],[Dividende annuel]]*Titres[[#This Row],[Nb d''actions]] -> 0 | W20: =Titres[[#This Row],[Dividende annuel]]/Titres[[#This Row],[Prix actuel]] -> 0.023483366 | X20: =Titres[[#This Row],[Dividende annuel]]/Titres[[#This Row],[Coût moyen]] -> 0.012908778 | Y20: 0 | Z20: =(((Titres[[#This Row],[Valeur au marché ($ local)]]-Titres[[#This Row],[Coût total]])+Titres[[#This Row],[Total - dividendes reçus]])/Titres[[#This Row],[Coût total]]) -> #DIV/0! | AA20: =SUM(Titres[[#This Row],[Janvier 2019]:[Août 2024]]) -> 70.1 | BZ20: 14.02 | CC20: 14.02 | CF20: 14.02 | CI20: 14.02 | CL20: 14.02
B21: =IF(C21="","",_xlfn.XLOOKUP(C21,Type_Compte,Num_Compte)) -> 20K6HE4 | C21: Marge (CAD) | D21: #VALUE! | E21: {=_FV(Titres[[#This Row],[Action]],"Code mnémonique",TRUE)} -> XSP | F21: {=_FV(D21,"Change")} -> Toronto Stock Exchange | G21: {=IFERROR(_FV(Titres[[#This Row],[Action]],"Industrie"),"")} | H21: Actions américaines | I21: {=_FV(D21,"Devise")} -> CAD | J21: 500 | K21: 55.91 | L21: =J21*K21 -> 27955 | M21: {=_FV(D21,"Prix")} -> 71.38 | N21: =J21*M21 -> 35690 | O21: =IF(Titres[[#This Row],[Devise]]="CAD",Titres[[#This Row],[Valeur au marché ($ local)]],Titres[[#This Row],[Valeur au marché ($ local)]]*Ressources!$I$3) -> 35690 | P21: {=(Titres[[#This Row],[Prix actuel]]-_FV(Titres[[#This Row],[Action]],"Clôture précédente",TRUE))*Titres[[#This Row],[Nb d''actions]]} -> -230 | Q21: =Titres[[#This Row],[Variation du jour ($)]]/(Titres[[#This Row],[Valeur au marché ($ local)]]-Titres[[#This Row],[Variation du jour ($)]]) -> -0.006403118 | R21: =Titres[[#This Row],[Valeur au marché ($ local)]]-Titres[[#This Row],[Coût total]] -> 7735 | S21: =Titres[[#This Row],[Gain non réalisé ($)]]/Titres[[#This Row],[Coût total]] -> 0.27669469 | T21: 0.556 | U21: =4*Titres[[#This Row],[Dividende trimestriel]] -> 2.224 | V21: =Titres[[#This Row],[Dividende annuel]]*Titres[[#This Row],[Nb d''actions]] -> 1112 | W21: =Titres[[#This Row],[Dividende annuel]]/Titres[[#This Row],[Prix actuel]] -> 0.031157187 | X21: =Titres[[#This Row],[Dividende annuel]]/Titres[[#This Row],[Coût moyen]] -> 0.039778215 | Z21: =(((Titres[[#This Row],[Valeur au marché ($ local)]]-Titres[[#This Row],[Coût total]])+Titres[[#This Row],[Total - dividendes reçus]])/Titres[[#This Row],[Coût total]]) -> 0.27969952 | AA21: =SUM(Titres[[#This Row],[Janvier 2019]:[Août 2024]]) -> 84 | CP21: 84 | CV21: 192.35 | DA21: 150 | DH21: 278
B22: =IF(C22="","",_xlfn.XLOOKUP(C22,Type_Compte,Num_Compte)) -> 20K6HZ6 | C22: CELI (CAD) | D22: #VALUE! | E22: {=_FV(Titres[[#This Row],[Action]],"Code mnémonique",TRUE)} -> CTC | F22: {=_FV(D22,"Change")} -> Toronto Stock Exchange | G22: {=IFERROR(_FV(Titres[[#This Row],[Action]],"Industrie"),"")} -> Diversified Retail | H22: Actions canadiennes | I22: {=_FV(D22,"Devise")} -> CAD | J22: 24 | K22: 224.3 | L22: =J22*K22 -> 5383.2 | M22: {=_FV(D22,"Prix")} -> 219.99 | N22: =J22*M22 -> 5279.76 | O22: =IF(Titres[[#This Row],[Devise]]="CAD",Titres[[#This Row],[Valeur au marché ($ local)]],Titres[[#This Row],[Valeur au marché ($ local)]]*Ressources!$I$3) -> 5279.76 | P22: {=(Titres[[#This Row],[Prix actuel]]-_FV(Titres[[#This Row],[Action]],"Clôture précédente",TRUE))*Titres[[#This Row],[Nb d''actions]]} -> 167.76 | Q22: =Titres[[#This Row],[Variation du jour ($)]]/(Titres[[#This Row],[Valeur au marché ($ local)]]-Titres[[#This Row],[Variation du jour ($)]]) -> 0.032816901 | R22: =Titres[[#This Row],[Valeur au marché ($ local)]]-Titres[[#This Row],[Coût total]] -> -103.44 | S22: =Titres[[#This Row],[Gain non réalisé ($)]]/Titres[[#This Row],[Coût total]] -> -0.019215337 | T22: 1.8 | U22: =4*Titres[[#This Row],[Dividende trimestriel]] -> 7.2 | V22: =Titres[[#This Row],[Dividende annuel]]*Titres[[#This Row],[Nb d''actions]] -> 172.8 | W22: =Titres[[#This Row],[Dividende annuel]]/Titres[[#This Row],[Prix actuel]] -> 0.03272876 | X22: =Titres[[#This Row],[Dividende annuel]]/Titres[[#This Row],[Coût moyen]] -> 0.032099866 | Y22: 12 | Z22: =(((Titres[[#This Row],[Valeur au marché ($ local)]]-Titres[[#This Row],[Coût total]])+Titres[[#This Row],[Total - dividendes reçus]])/Titres[[#This Row],[Coût total]]) -> -0.015180562 | AA22: =SUM(Titres[[#This Row],[Janvier 2019]:[Août 2024]]) -> 21.72 | CE22: =25.55-3.83 -> 21.72 | CR22: 21 | CU22: 29.75 | CX22: 30.18 | DA22: 30.18 | DD22: 42.6 | DG22: 42.6
B23: =IF(C23="","",_xlfn.XLOOKUP(C23,Type_Compte,Num_Compte)) -> 20K6HZ6 | C23: CELI (CAD) | D23: #VALUE! | E23: {=_FV(Titres[[#This Row],[Action]],"Code mnémonique",TRUE)} -> CU | F23: {=_FV(D23,"Change")} -> Toronto Stock Exchange | G23: {=IFERROR(_FV(Titres[[#This Row],[Action]],"Industrie"),"")} -> Multiline Utilities | H23: Actions canadiennes | I23: {=_FV(D23,"Devise")} -> CAD | J23: 150 | K23: 44.48 | L23: =J23*K23 -> 6672 | M23: {=_FV(D23,"Prix")} -> 47.92 | N23: =J23*M23 -> 7188 | O23: =IF(Titres[[#This Row],[Devise]]="CAD",Titres[[#This Row],[Valeur au marché ($ local)]],Titres[[#This Row],[Valeur au marché ($ local)]]*Ressources!$I$3) -> 7188 | P23: {=(Titres[[#This Row],[Prix actuel]]-_FV(Titres[[#This Row],[Action]],"Clôture précédente",TRUE))*Titres[[#This Row],[Nb d''actions]]} -> -43.5 | Q23: =Titres[[#This Row],[Variation du jour ($)]]/(Titres[[#This Row],[Valeur au marché ($ local)]]-Titres[[#This Row],[Variation du jour ($)]]) -> -0.0060153495 | R23: =Titres[[#This Row],[Valeur au marché ($ local)]]-Titres[[#This Row],[Coût total]] -> 516 | S23: =Titres[[#This Row],[Gain non réalisé ($)]]/Titres[[#This Row],[Coût total]] -> 0.077338129 | T23: 0.462 | U23: =4*Titres[[#This Row],[Dividende trimestriel]] -> 1.848 | V23: =Titres[[#This Row],[Dividende annuel]]*Titres[[#This Row],[Nb d''actions]] -> 277.2 | W23: =Titres[[#This Row],[Dividende annuel]]/Titres[[#This Row],[Prix actuel]] -> 0.038564274 | X23: =Titres[[#This Row],[Dividende annuel]]/Titres[[#This Row],[Coût moyen]] -> 0.041546763 | Z23: =(((Titres[[#This Row],[Valeur au marché ($ local)]]-Titres[[#This Row],[Coût total]])+Titres[[#This Row],[Total - dividendes reçus]])/Titres[[#This Row],[Coût total]]) -> 0.080593525 | AA23: =SUM(Titres[[#This Row],[Janvier 2019]:[Août 2024]]) -> 21.72 | CE23: =25.55-3.83 -> 21.72
